<sdf version='1.6'>
  <model name='dogbot'>
    <link name='base_link'>
      <pose frame=''>0 0 0 0 -0 0</pose>
      <inertial>
        <pose frame=''>0 0 0 0 -0 0</pose>
        <mass>9.301</mass>
        <inertia>
          <ixx>0.41</ixx>
          <ixy>0</ixy>
          <ixz>0</ixz>
          <iyy>0.091</iyy>
          <iyz>0</iyz>
          <izz>0.482</izz>
        </inertia>
      </inertial>
      <collision name='base_link_fixed_joint_lump__body_collision'>
        <pose frame=''>0 0 0 0 -0 0</pose>
        <geometry>
          <box>
            <size>0.177 0.433 0.105</size>
          </box>
        </geometry>
        <surface>
          <contact>
            <ode>
              <kp>1e+06</kp>
              <kd>1</kd>
            </ode>
          </contact>
          <friction>
            <ode>
              <mu>200</mu>
              <mu2>100</mu2>
            </ode>
          </friction>
        </surface>
      </collision>
      <collision name='base_link_fixed_joint_lump__body_collision_1'>
        <pose frame=''>0.0885 0 0 1.5708 -0 0</pose>
        <geometry>
          <cylinder>
            <length>0.433</length>
            <radius>0.0525</radius>
          </cylinder>
        </geometry>
        <surface>
          <contact>
            <ode>
              <kp>1e+06</kp>
              <kd>1</kd>
            </ode>
          </contact>
          <friction>
            <ode>
              <mu>200</mu>
              <mu2>100</mu2>
            </ode>
          </friction>
        </surface>
      </collision>
      <collision name='base_link_fixed_joint_lump__body_collision_2'>
        <pose frame=''>-0.0885 0 0 1.5708 -0 0</pose>
        <geometry>
          <cylinder>
            <length>0.433</length>
            <radius>0.0525</radius>
          </cylinder>
        </geometry>
        <surface>
          <contact>
            <ode>
              <kp>1e+06</kp>
              <kd>1</kd>
            </ode>
          </contact>
          <friction>
            <ode>
              <mu>200</mu>
              <mu2>100</mu2>
            </ode>
          </friction>
        </surface>
      </collision>
      <collision name='base_link_fixed_joint_lump__body_collision_3'>
        <pose frame=''>0 0.2825 0 0 -0 0</pose>
        <geometry>
          <box>
            <size>0.035 0.132 0.105</size>
          </box>
        </geometry>
        <surface>
          <contact>
            <ode>
              <kp>1e+06</kp>
              <kd>1</kd>
            </ode>
          </contact>
          <friction>
            <ode>
              <mu>200</mu>
              <mu2>100</mu2>
            </ode>
          </friction>
        </surface>
      </collision>
      <collision name='base_link_fixed_joint_lump__body_collision_4'>
        <pose frame=''>0 -0.2825 0 0 -0 0</pose>
        <geometry>
          <box>
            <size>0.035 0.132 0.105</size>
          </box>
        </geometry>
        <surface>
          <contact>
            <ode>
              <kp>1e+06</kp>
              <kd>1</kd>
            </ode>
          </contact>
          <friction>
            <ode>
              <mu>200</mu>
              <mu2>100</mu2>
            </ode>
          </friction>
        </surface>
      </collision>
      <collision name='base_link_fixed_joint_lump__body_collision_5'>
        <pose frame=''>0 0.3975 0 0 -0 0</pose>
        <geometry>
          <box>
            <size>0.177 0.08 0.105</size>
          </box>
        </geometry>
        <surface>
          <contact>
            <ode>
              <kp>1e+06</kp>
              <kd>1</kd>
            </ode>
          </contact>
          <friction>
            <ode>
              <mu>200</mu>
              <mu2>100</mu2>
            </ode>
          </friction>
        </surface>
      </collision>
      <collision name='base_link_fixed_joint_lump__body_collision_6'>
        <pose frame=''>0.0885 0.3975 0 1.5708 -0 0</pose>
        <geometry>
          <cylinder>
            <length>0.08</length>
            <radius>0.0525</radius>
          </cylinder>
        </geometry>
        <surface>
          <contact>
            <ode>
              <kp>1e+06</kp>
              <kd>1</kd>
            </ode>
          </contact>
          <friction>
            <ode>
              <mu>200</mu>
              <mu2>100</mu2>
            </ode>
          </friction>
        </surface>
      </collision>
      <collision name='base_link_fixed_joint_lump__body_collision_7'>
        <pose frame=''>-0.0885 0.3975 0 1.5708 -0 0</pose>
        <geometry>
          <cylinder>
            <length>0.08</length>
            <radius>0.0525</radius>
          </cylinder>
        </geometry>
        <surface>
          <contact>
            <ode>
              <kp>1e+06</kp>
              <kd>1</kd>
            </ode>
          </contact>
          <friction>
            <ode>
              <mu>200</mu>
              <mu2>100</mu2>
            </ode>
          </friction>
        </surface>
      </collision>
      <collision name='base_link_fixed_joint_lump__body_collision_8'>
        <pose frame=''>0 -0.3975 0 0 -0 0</pose>
        <geometry>
          <box>
            <size>0.177 0.08 0.105</size>
          </box>
        </geometry>
        <surface>
          <contact>
            <ode>
              <kp>1e+06</kp>
              <kd>1</kd>
            </ode>
          </contact>
          <friction>
            <ode>
              <mu>200</mu>
              <mu2>100</mu2>
            </ode>
          </friction>
        </surface>
      </collision>
      <collision name='base_link_fixed_joint_lump__body_collision_9'>
        <pose frame=''>0.0885 -0.3975 0 1.5708 -0 0</pose>
        <geometry>
          <cylinder>
            <length>0.08</length>
            <radius>0.0525</radius>
          </cylinder>
        </geometry>
        <surface>
          <contact>
            <ode>
              <kp>1e+06</kp>
              <kd>1</kd>
            </ode>
          </contact>
          <friction>
            <ode>
              <mu>200</mu>
              <mu2>100</mu2>
            </ode>
          </friction>
        </surface>
      </collision>
      <collision name='base_link_fixed_joint_lump__body_collision_10'>
        <pose frame=''>-0.0885 -0.3975 0 1.5708 -0 0</pose>
        <geometry>
          <cylinder>
            <length>0.08</length>
            <radius>0.0525</radius>
          </cylinder>
        </geometry>
        <surface>
          <contact>
            <ode>
              <kp>1e+06</kp>
              <kd>1</kd>
            </ode>
          </contact>
          <friction>
            <ode>
              <mu>200</mu>
              <mu2>100</mu2>
            </ode>
          </friction>
        </surface>
      </collision>
      <visual name='base_link_fixed_joint_lump__body_visual'>
        <pose frame=''>0 0 0 -1.5708 0 0</pose>
        <geometry>
          <mesh>
            <scale>1 1 1</scale>
            <uri>model://dogbot_description/meshes/body.dae</uri>
          </mesh>
        </geometry>
        <material>
          <script>
            <uri>__default__</uri>
            <name>__default__</name>
          </script>
        </material>
      </visual>
      <visual name='base_link_fixed_joint_lump__bodytext_visual_1'>
        <pose frame=''>0 0 0 -1.5708 0 0</pose>
        <geometry>
          <mesh>
            <scale>1 1 1</scale>
            <uri>model://dogbot_description/meshes/bodyTEXT.dae</uri>
          </mesh>
        </geometry>
      </visual>
      <gravity>1</gravity>
      <velocity_decay/>
    </link>
    <link name='back_left_hip'>
      <pose frame=''>-0.088 -0.2875 0 0 -0 0</pose>
      <inertial>
        <pose frame=''>-0.0074 0 0 0 -0 0</pose>
        <mass>0.836</mass>
        <inertia>
          <ixx>0.00213</ixx>
          <ixy>0</ixy>
          <ixz>0</ixz>
          <iyy>0.00147</iyy>
          <iyz>0</iyz>
          <izz>0.00172</izz>
        </inertia>
      </inertial>
      <collision name='back_left_hip_collision'>
        <pose frame=''>-0.02 0 0 3.14159 1.57079 3.14159</pose>
        <geometry>
          <cylinder>
            <length>0.08</length>
            <radius>0.0525</radius>
          </cylinder>
        </geometry>
      </collision>
      <visual name='back_left_hip_visual'>
        <pose frame=''>0 0 0 1.5708 0 -3.14159</pose>
        <geometry>
          <mesh>
            <scale>1 1 1</scale>
            <uri>model://dogbot_description/meshes/hip.dae</uri>
          </mesh>
        </geometry>
      </visual>
    </link>
    <joint name='back_left_roll_joint' type='revolute'>
      <child>back_left_hip</child>
      <parent>base_link</parent>
      <axis>
        <xyz>0 -1 0</xyz>
        <limit>
          <lower>-1.7453</lower>
          <upper>1.7453</upper>
          <effort>60</effort>
          <velocity>6</velocity>
        </limit>
        <dynamics>
          <spring_reference>0</spring_reference>
          <spring_stiffness>0</spring_stiffness>
        </dynamics>
        <use_parent_model_frame>1</use_parent_model_frame>
      </axis>
    </joint>
    <link name='back_left_upperleg'>
      <pose frame=''>-0.18675 -0.2875 0 0 -0 0</pose>
      <inertial>
        <pose frame=''>-0.0418 0 -0.0517 0 -0 0</pose>
        <mass>1.851</mass>
        <inertia>
          <ixx>0.0238</ixx>
          <ixy>0</ixy>
          <ixz>0</ixz>
          <iyy>0.0252</iyy>
          <iyz>0</iyz>
          <izz>0.0044</izz>
        </inertia>
      </inertial>
      <collision name='back_left_upperleg_collision'>
        <pose frame=''>-0.03 0 0 3.14159 1.57079 3.14159</pose>
        <geometry>
          <cylinder>
            <length>0.13</length>
            <radius>0.0525</radius>
          </cylinder>
        </geometry>
      </collision>
      <collision name='back_left_upperleg_collision_1'>
        <pose frame=''>0 0 -0.135 0 -0 0</pose>
        <geometry>
          <cylinder>
            <length>0.27</length>
            <radius>0.033</radius>
          </cylinder>
        </geometry>
      </collision>
      <collision name='back_left_upperleg_collision_2'>
        <pose frame=''>0 0 -0.135 0 -0 0</pose>
        <geometry>
          <box>
            <size>0.025 0.084 0.27</size>
          </box>
        </geometry>
      </collision>
      <collision name='back_left_upperleg_collision_3'>
        <pose frame=''>-0.046 0 -0.126 0 -0 0</pose>
        <geometry>
          <box>
            <size>0.026 0.074 0.138</size>
          </box>
        </geometry>
      </collision>
      <collision name='back_left_upperleg_collision_4'>
        <pose frame=''>-0.03 0 -0.315 3.14159 1.57079 3.14159</pose>
        <geometry>
          <cylinder>
            <length>0.018</length>
            <radius>0.017</radius>
          </cylinder>
        </geometry>
      </collision>
      <collision name='back_left_upperleg_collision_5'>
        <pose frame=''>0.036 0 -0.315 3.14159 1.57079 3.14159</pose>
        <geometry>
          <cylinder>
            <length>0.013</length>
            <radius>0.017</radius>
          </cylinder>
        </geometry>
      </collision>
      <visual name='back_left_upperleg_visual'>
        <pose frame=''>0 0 0 -1.5708 -0 3.14159</pose>
        <geometry>
          <mesh>
            <scale>1 1 1</scale>
            <uri>model://dogbot_description/meshes/LegUpper_withCover.dae</uri>
          </mesh>
        </geometry>
      </visual>
    </link>
    <joint name='back_left_pitch_joint' type='revolute'>
      <child>back_left_upperleg</child>
      <parent>back_left_hip</parent>
      <axis>
        <xyz>-1 0 0</xyz>
        <limit>
          <lower>-1.5708</lower>
          <upper>3.14159</upper>
          <effort>60</effort>
          <velocity>6</velocity>
        </limit>
        <dynamics>
          <spring_reference>0</spring_reference>
          <spring_stiffness>0</spring_stiffness>
        </dynamics>
        <use_parent_model_frame>1</use_parent_model_frame>
      </axis>
    </joint>
    <link name='back_left_lowerleg'>
      <pose frame=''>-0.18675 -0.2875 -0.315 0 -0 0</pose>
      <inertial>
        <pose frame=''>0 -0.028904 -0.143425 0 -0 0</pose>
        <mass>0.303</mass>
        <inertia>
          <ixx>0.00529148</ixx>
          <ixy>0</ixy>
          <ixz>0</ixz>
          <iyy>0.00511064</iyy>
          <iyz>-4.15933e-06</iyz>
          <izz>0.000800838</izz>
        </inertia>
      </inertial>
      <collision name='back_left_lowerleg_collision'>
        <pose frame=''>0 0 0 3.14159 1.57079 3.14159</pose>
        <geometry>
          <cylinder>
            <length>0.033</length>
            <radius>0.042</radius>
          </cylinder>
        </geometry>
        <surface>
          <contact>
            <ode>
              <kp>1e+06</kp>
              <kd>1</kd>
            </ode>
          </contact>
          <friction>
            <ode>
              <mu>2000</mu>
              <mu2>1000</mu2>
            </ode>
          </friction>
        </surface>
      </collision>
      <collision name='back_left_lowerleg_collision_1'>
        <pose frame=''>0.024 -0.0375 -0.0055 0 -0 0</pose>
        <geometry>
          <box>
            <size>0.02 0.017 0.065</size>
          </box>
        </geometry>
        <surface>
          <contact>
            <ode>
              <kp>1e+06</kp>
              <kd>1</kd>
            </ode>
          </contact>
          <friction>
            <ode>
              <mu>2000</mu>
              <mu2>1000</mu2>
            </ode>
          </friction>
        </surface>
      </collision>
      <collision name='back_left_lowerleg_collision_2'>
        <pose frame=''>-0.024 -0.0375 -0.0055 0 -0 0</pose>
        <geometry>
          <box>
            <size>0.02 0.017 0.065</size>
          </box>
        </geometry>
        <surface>
          <contact>
            <ode>
              <kp>1e+06</kp>
              <kd>1</kd>
            </ode>
          </contact>
          <friction>
            <ode>
              <mu>2000</mu>
              <mu2>1000</mu2>
            </ode>
          </friction>
        </surface>
      </collision>
      <collision name='back_left_lowerleg_collision_3'>
        <pose frame=''>0.01575 -0.0375 -0.145 0 0.04996 0</pose>
        <geometry>
          <cylinder>
            <length>0.29</length>
            <radius>0.006</radius>
          </cylinder>
        </geometry>
        <surface>
          <contact>
            <ode>
              <kp>1e+06</kp>
              <kd>1</kd>
            </ode>
          </contact>
          <friction>
            <ode>
              <mu>2000</mu>
              <mu2>1000</mu2>
            </ode>
          </friction>
        </surface>
      </collision>
      <collision name='back_left_lowerleg_collision_4'>
        <pose frame=''>-0.01575 -0.0375 -0.145 0 -0.04996 0</pose>
        <geometry>
          <cylinder>
            <length>0.29</length>
            <radius>0.006</radius>
          </cylinder>
        </geometry>
        <surface>
          <contact>
            <ode>
              <kp>1e+06</kp>
              <kd>1</kd>
            </ode>
          </contact>
          <friction>
            <ode>
              <mu>2000</mu>
              <mu2>1000</mu2>
            </ode>
          </friction>
        </surface>
      </collision>
      <collision name='back_left_lowerleg_fixed_joint_lump__back_left_foot_collision_5'>
        <pose frame=''>0 -0.035 -0.3 0 -0 0</pose>
        <geometry>
          <sphere>
            <radius>0.028</radius>
          </sphere>
        </geometry>
        <surface>
          <contact>
            <ode>
              <kp>1e+06</kp>
              <kd>1</kd>
            </ode>
          </contact>
          <friction>
            <ode>
              <mu>2000</mu>
              <mu2>1000</mu2>
            </ode>
          </friction>
        </surface>
      </collision>
      <visual name='back_left_lowerleg_visual'>
        <pose frame=''>0 0 0 -1.5708 0 0</pose>
        <geometry>
          <mesh>
            <scale>1 1 1</scale>
            <uri>model://dogbot_description/meshes/LegLower_nofoot.dae</uri>
          </mesh>
        </geometry>
        <material>
          <script>
            <uri>__default__</uri>
            <name>__default__</name>
          </script>
        </material>
      </visual>
      <visual name='back_left_lowerleg_fixed_joint_lump__back_left_foot_visual_1'>
        <pose frame=''>0 0 0 -1.5708 0 0</pose>
        <geometry>
          <mesh>
            <scale>1 1 1</scale>
            <uri>model://dogbot_description/meshes/foot.dae</uri>
          </mesh>
        </geometry>
        <material>
          <script>
            <uri>__default__</uri>
            <name>__default__</name>
          </script>
        </material>
      </visual>
      <velocity_decay/>
      <self_collide>1</self_collide>
      <gravity>1</gravity>
      <velocity_decay/>
      <sensor name='back_left_contactsensor_sensor' type='contact'>
        <always_on>1</always_on>
        <contact>
          <collision>back_left_lowerleg_fixed_joint_lump__back_left_foot_collision_5</collision>
          <topic>__default_topic__</topic>
        </contact>
        <plugin name='back_left_foot_plugin' filename='libgazebo_ros_bumper.so'>
          <bumperTopicName>back_left_contactsensor_state</bumperTopicName>
          <frameName>world</frameName>
        </plugin>
        <pose frame=''>0 0 0 0 -0 0</pose>
      </sensor>
    </link>
    <joint name='back_left_knee_joint' type='revolute'>
      <child>back_left_lowerleg</child>
      <parent>back_left_upperleg</parent>
      <axis>
        <xyz>1 0 0</xyz>
        <limit>
          <lower>-2.61795</lower>
          <upper>0.02</upper>
          <effort>60</effort>
          <velocity>6</velocity>
        </limit>
        <dynamics>
          <spring_reference>0</spring_reference>
          <spring_stiffness>0</spring_stiffness>
        </dynamics>
        <use_parent_model_frame>1</use_parent_model_frame>
      </axis>
    </joint>
    <link name='back_right_hip'>
      <pose frame=''>0.088 -0.2875 0 0 -0 0</pose>
      <inertial>
        <pose frame=''>0.0074 0 0 0 -0 0</pose>
        <mass>0.836</mass>
        <inertia>
          <ixx>0.00213</ixx>
          <ixy>0</ixy>
          <ixz>0</ixz>
          <iyy>0.00147</iyy>
          <iyz>0</iyz>
          <izz>0.00172</izz>
        </inertia>
      </inertial>
      <collision name='back_right_hip_collision'>
        <pose frame=''>0.02 0 0 3.14159 1.57079 3.14159</pose>
        <geometry>
          <cylinder>
            <length>0.08</length>
            <radius>0.0525</radius>
          </cylinder>
        </geometry>
      </collision>
      <visual name='back_right_hip_visual'>
        <pose frame=''>0 0 0 -1.5708 0 0</pose>
        <geometry>
          <mesh>
            <scale>1 1 1</scale>
            <uri>model://dogbot_description/meshes/hip.dae</uri>
          </mesh>
        </geometry>
      </visual>
    </link>
    <joint name='back_right_roll_joint' type='revolute'>
      <child>back_right_hip</child>
      <parent>base_link</parent>
      <axis>
        <xyz>0 -1 0</xyz>
        <limit>
          <lower>-1.7453</lower>
          <upper>1.7453</upper>
          <effort>60</effort>
          <velocity>6</velocity>
        </limit>
        <dynamics>
          <spring_reference>0</spring_reference>
          <spring_stiffness>0</spring_stiffness>
        </dynamics>
        <use_parent_model_frame>1</use_parent_model_frame>
      </axis>
    </joint>
    <link name='back_right_upperleg'>
      <pose frame=''>0.18675 -0.2875 0 0 -0 0</pose>
      <inertial>
        <pose frame=''>0.0418 0 -0.0517 0 -0 0</pose>
        <mass>1.851</mass>
        <inertia>
          <ixx>0.0238</ixx>
          <ixy>0</ixy>
          <ixz>0</ixz>
          <iyy>0.0252</iyy>
          <iyz>0</iyz>
          <izz>0.0044</izz>
        </inertia>
      </inertial>
      <collision name='back_right_upperleg_collision'>
        <pose frame=''>0.03 0 0 3.14159 1.57079 3.14159</pose>
        <geometry>
          <cylinder>
            <length>0.13</length>
            <radius>0.0525</radius>
          </cylinder>
        </geometry>
      </collision>
      <collision name='back_right_upperleg_collision_1'>
        <pose frame=''>0 0 -0.135 0 -0 0</pose>
        <geometry>
          <cylinder>
            <length>0.27</length>
            <radius>0.033</radius>
          </cylinder>
        </geometry>
      </collision>
      <collision name='back_right_upperleg_collision_2'>
        <pose frame=''>0 0 -0.135 0 -0 0</pose>
        <geometry>
          <box>
            <size>0.025 0.084 0.27</size>
          </box>
        </geometry>
      </collision>
      <collision name='back_right_upperleg_collision_3'>
        <pose frame=''>0.046 0 -0.126 0 -0 0</pose>
        <geometry>
          <box>
            <size>0.026 0.074 0.138</size>
          </box>
        </geometry>
      </collision>
      <collision name='back_right_upperleg_collision_4'>
        <pose frame=''>0.03 0 -0.315 3.14159 1.57079 3.14159</pose>
        <geometry>
          <cylinder>
            <length>0.018</length>
            <radius>0.017</radius>
          </cylinder>
        </geometry>
      </collision>
      <collision name='back_right_upperleg_collision_5'>
        <pose frame=''>-0.036 0 -0.315 3.14159 1.57079 3.14159</pose>
        <geometry>
          <cylinder>
            <length>0.013</length>
            <radius>0.017</radius>
          </cylinder>
        </geometry>
      </collision>
      <visual name='back_right_upperleg_visual'>
        <pose frame=''>0 0 0 -1.5708 0 0</pose>
        <geometry>
          <mesh>
            <scale>1 1 1</scale>
            <uri>model://dogbot_description/meshes/LegUpper_withCover.dae</uri>
          </mesh>
        </geometry>
      </visual>
    </link>
    <joint name='back_right_pitch_joint' type='revolute'>
      <child>back_right_upperleg</child>
      <parent>back_right_hip</parent>
      <axis>
        <xyz>1 0 0</xyz>
        <limit>
          <lower>-3.14159</lower>
          <upper>1.5708</upper>
          <effort>60</effort>
          <velocity>6</velocity>
        </limit>
        <dynamics>
          <spring_reference>0</spring_reference>
          <spring_stiffness>0</spring_stiffness>
        </dynamics>
        <use_parent_model_frame>1</use_parent_model_frame>
      </axis>
    </joint>
    <link name='back_right_lowerleg'>
      <pose frame=''>0.18675 -0.2875 -0.315 0 -0 0</pose>
      <inertial>
        <pose frame=''>0 -0.028904 -0.143425 0 -0 0</pose>
        <mass>0.303</mass>
        <inertia>
          <ixx>0.00529148</ixx>
          <ixy>0</ixy>
          <ixz>0</ixz>
          <iyy>0.00511064</iyy>
          <iyz>-4.15933e-06</iyz>
          <izz>0.000800838</izz>
        </inertia>
      </inertial>
      <collision name='back_right_lowerleg_collision'>
        <pose frame=''>0 0 0 3.14159 1.57079 3.14159</pose>
        <geometry>
          <cylinder>
            <length>0.033</length>
            <radius>0.042</radius>
          </cylinder>
        </geometry>
        <surface>
          <contact>
            <ode>
              <kp>1e+06</kp>
              <kd>1</kd>
            </ode>
          </contact>
          <friction>
            <ode>
              <mu>2000</mu>
              <mu2>1000</mu2>
            </ode>
          </friction>
        </surface>
      </collision>
      <collision name='back_right_lowerleg_collision_1'>
        <pose frame=''>0.024 -0.0375 -0.0055 0 -0 0</pose>
        <geometry>
          <box>
            <size>0.02 0.017 0.065</size>
          </box>
        </geometry>
        <surface>
          <contact>
            <ode>
              <kp>1e+06</kp>
              <kd>1</kd>
            </ode>
          </contact>
          <friction>
            <ode>
              <mu>2000</mu>
              <mu2>1000</mu2>
            </ode>
          </friction>
        </surface>
      </collision>
      <collision name='back_right_lowerleg_collision_2'>
        <pose frame=''>-0.024 -0.0375 -0.0055 0 -0 0</pose>
        <geometry>
          <box>
            <size>0.02 0.017 0.065</size>
          </box>
        </geometry>
        <surface>
          <contact>
            <ode>
              <kp>1e+06</kp>
              <kd>1</kd>
            </ode>
          </contact>
          <friction>
            <ode>
              <mu>2000</mu>
              <mu2>1000</mu2>
            </ode>
          </friction>
        </surface>
      </collision>
      <collision name='back_right_lowerleg_collision_3'>
        <pose frame=''>0.01575 -0.0375 -0.145 0 0.04996 0</pose>
        <geometry>
          <cylinder>
            <length>0.29</length>
            <radius>0.006</radius>
          </cylinder>
        </geometry>
        <surface>
          <contact>
            <ode>
              <kp>1e+06</kp>
              <kd>1</kd>
            </ode>
          </contact>
          <friction>
            <ode>
              <mu>2000</mu>
              <mu2>1000</mu2>
            </ode>
          </friction>
        </surface>
      </collision>
      <collision name='back_right_lowerleg_collision_4'>
        <pose frame=''>-0.01575 -0.0375 -0.145 0 -0.04996 0</pose>
        <geometry>
          <cylinder>
            <length>0.29</length>
            <radius>0.006</radius>
          </cylinder>
        </geometry>
        <surface>
          <contact>
            <ode>
              <kp>1e+06</kp>
              <kd>1</kd>
            </ode>
          </contact>
          <friction>
            <ode>
              <mu>2000</mu>
              <mu2>1000</mu2>
            </ode>
          </friction>
        </surface>
      </collision>
      <collision name='back_right_lowerleg_fixed_joint_lump__back_right_foot_collision_5'>
        <pose frame=''>0 -0.035 -0.3 0 -0 0</pose>
        <geometry>
          <sphere>
            <radius>0.028</radius>
          </sphere>
        </geometry>
        <surface>
          <contact>
            <ode>
              <kp>1e+06</kp>
              <kd>1</kd>
            </ode>
          </contact>
          <friction>
            <ode>
              <mu>2000</mu>
              <mu2>1000</mu2>
            </ode>
          </friction>
        </surface>
      </collision>
      <visual name='back_right_lowerleg_visual'>
        <pose frame=''>0 0 0 -1.5708 0 0</pose>
        <geometry>
          <mesh>
            <scale>1 1 1</scale>
            <uri>model://dogbot_description/meshes/LegLower_nofoot.dae</uri>
          </mesh>
        </geometry>
        <material>
          <script>
            <uri>__default__</uri>
            <name>__default__</name>
          </script>
        </material>
      </visual>
      <visual name='back_right_lowerleg_fixed_joint_lump__back_right_foot_visual_1'>
        <pose frame=''>0 0 0 -1.5708 0 0</pose>
        <geometry>
          <mesh>
            <scale>1 1 1</scale>
            <uri>model://dogbot_description/meshes/foot.dae</uri>
          </mesh>
        </geometry>
        <material>
          <script>
            <uri>__default__</uri>
            <name>__default__</name>
          </script>
        </material>
      </visual>
      <velocity_decay/>
      <self_collide>1</self_collide>
      <gravity>1</gravity>
      <velocity_decay/>
      <sensor name='back_right_contactsensor_sensor' type='contact'>
        <always_on>1</always_on>
        <contact>
          <collision>back_right_lowerleg_fixed_joint_lump__back_right_foot_collision_5</collision>
          <topic>__default_topic__</topic>
        </contact>
        <plugin name='back_right_foot_plugin' filename='libgazebo_ros_bumper.so'>
          <bumperTopicName>back_right_contactsensor_state</bumperTopicName>
          <frameName>world</frameName>
        </plugin>
        <pose frame=''>0 0 0 0 -0 0</pose>
      </sensor>
    </link>
    <joint name='back_right_knee_joint' type='revolute'>
      <child>back_right_lowerleg</child>
      <parent>back_right_upperleg</parent>
      <axis>
        <xyz>-1 0 0</xyz>
        <limit>
          <lower>-0.02</lower>
          <upper>2.61795</upper>
          <effort>60</effort>
          <velocity>6</velocity>
        </limit>
        <dynamics>
          <spring_reference>0</spring_reference>
          <spring_stiffness>0</spring_stiffness>
        </dynamics>
        <use_parent_model_frame>1</use_parent_model_frame>
      </axis>
    </joint>
    <link name='front_left_hip'>
      <pose frame=''>-0.088 0.2875 0 0 -0 0</pose>
      <inertial>
        <pose frame=''>-0.0074 0 0 0 -0 0</pose>
        <mass>0.836</mass>
        <inertia>
          <ixx>0.00213</ixx>
          <ixy>0</ixy>
          <ixz>0</ixz>
          <iyy>0.00147</iyy>
          <iyz>0</iyz>
          <izz>0.00172</izz>
        </inertia>
      </inertial>
      <collision name='front_left_hip_collision'>
        <pose frame=''>-0.02 0 0 3.14159 1.57079 3.14159</pose>
        <geometry>
          <cylinder>
            <length>0.08</length>
            <radius>0.0525</radius>
          </cylinder>
        </geometry>
      </collision>
      <visual name='front_left_hip_visual'>
        <pose frame=''>0 0 0 1.5708 0 -3.14159</pose>
        <geometry>
          <mesh>
            <scale>1 1 1</scale>
            <uri>model://dogbot_description/meshes/hip.dae</uri>
          </mesh>
        </geometry>
      </visual>
    </link>
    <joint name='front_left_roll_joint' type='revolute'>
      <child>front_left_hip</child>
      <parent>base_link</parent>
      <axis>
        <xyz>0 1 0</xyz>
        <limit>
          <lower>-1.7453</lower>
          <upper>1.7453</upper>
          <effort>60</effort>
          <velocity>6</velocity>
        </limit>
        <dynamics>
          <spring_reference>0</spring_reference>
          <spring_stiffness>0</spring_stiffness>
        </dynamics>
        <use_parent_model_frame>1</use_parent_model_frame>
      </axis>
    </joint>
    <link name='front_left_upperleg'>
      <pose frame=''>-0.18675 0.2875 0 0 -0 0</pose>
      <inertial>
        <pose frame=''>-0.0418 0 -0.0517 0 -0 0</pose>
        <mass>1.851</mass>
        <inertia>
          <ixx>0.0238</ixx>
          <ixy>0</ixy>
          <ixz>0</ixz>
          <iyy>0.0252</iyy>
          <iyz>0</iyz>
          <izz>0.0044</izz>
        </inertia>
      </inertial>
      <collision name='front_left_upperleg_collision'>
        <pose frame=''>-0.03 0 0 3.14159 1.57079 3.14159</pose>
        <geometry>
          <cylinder>
            <length>0.13</length>
            <radius>0.0525</radius>
          </cylinder>
        </geometry>
      </collision>
      <collision name='front_left_upperleg_collision_1'>
        <pose frame=''>0 0 -0.135 0 -0 0</pose>
        <geometry>
          <cylinder>
            <length>0.27</length>
            <radius>0.033</radius>
          </cylinder>
        </geometry>
      </collision>
      <collision name='front_left_upperleg_collision_2'>
        <pose frame=''>0 0 -0.135 0 -0 0</pose>
        <geometry>
          <box>
            <size>0.025 0.084 0.27</size>
          </box>
        </geometry>
      </collision>
      <collision name='front_left_upperleg_collision_3'>
        <pose frame=''>-0.046 0 -0.126 0 -0 0</pose>
        <geometry>
          <box>
            <size>0.026 0.074 0.138</size>
          </box>
        </geometry>
      </collision>
      <collision name='front_left_upperleg_collision_4'>
        <pose frame=''>-0.03 0 -0.315 3.14159 1.57079 3.14159</pose>
        <geometry>
          <cylinder>
            <length>0.018</length>
            <radius>0.017</radius>
          </cylinder>
        </geometry>
      </collision>
      <collision name='front_left_upperleg_collision_5'>
        <pose frame=''>0.036 0 -0.315 3.14159 1.57079 3.14159</pose>
        <geometry>
          <cylinder>
            <length>0.013</length>
            <radius>0.017</radius>
          </cylinder>
        </geometry>
      </collision>
      <visual name='front_left_upperleg_visual'>
        <pose frame=''>0 0 0 -1.5708 -0 3.14159</pose>
        <geometry>
          <mesh>
            <scale>1 1 1</scale>
            <uri>model://dogbot_description/meshes/LegUpper_withCover.dae</uri>
          </mesh>
        </geometry>
      </visual>
    </link>
    <joint name='front_left_pitch_joint' type='revolute'>
      <child>front_left_upperleg</child>
      <parent>front_left_hip</parent>
      <axis>
        <xyz>-1 0 0</xyz>
        <limit>
          <lower>-1.5708</lower>
          <upper>3.14159</upper>
          <effort>60</effort>
          <velocity>6</velocity>
        </limit>
        <dynamics>
          <spring_reference>0</spring_reference>
          <spring_stiffness>0</spring_stiffness>
        </dynamics>
        <use_parent_model_frame>1</use_parent_model_frame>
      </axis>
    </joint>
    <link name='front_left_lowerleg'>
      <pose frame=''>-0.18675 0.2875 -0.315 0 -0 0</pose>
      <inertial>
        <pose frame=''>0 -0.028904 -0.143425 0 -0 0</pose>
        <mass>0.303</mass>
        <inertia>
          <ixx>0.00529148</ixx>
          <ixy>0</ixy>
          <ixz>0</ixz>
          <iyy>0.00511064</iyy>
          <iyz>-4.15933e-06</iyz>
          <izz>0.000800838</izz>
        </inertia>
      </inertial>
      <collision name='front_left_lowerleg_collision'>
        <pose frame=''>0 0 0 3.14159 1.57079 3.14159</pose>
        <geometry>
          <cylinder>
            <length>0.033</length>
            <radius>0.042</radius>
          </cylinder>
        </geometry>
        <surface>
          <contact>
            <ode>
              <kp>1e+06</kp>
              <kd>1</kd>
            </ode>
          </contact>
          <friction>
            <ode>
              <mu>2000</mu>
              <mu2>1000</mu2>
            </ode>
          </friction>
        </surface>
      </collision>
      <collision name='front_left_lowerleg_collision_1'>
        <pose frame=''>0.024 -0.0375 -0.0055 0 -0 0</pose>
        <geometry>
          <box>
            <size>0.02 0.017 0.065</size>
          </box>
        </geometry>
        <surface>
          <contact>
            <ode>
              <kp>1e+06</kp>
              <kd>1</kd>
            </ode>
          </contact>
          <friction>
            <ode>
              <mu>2000</mu>
              <mu2>1000</mu2>
            </ode>
          </friction>
        </surface>
      </collision>
      <collision name='front_left_lowerleg_collision_2'>
        <pose frame=''>-0.024 -0.0375 -0.0055 0 -0 0</pose>
        <geometry>
          <box>
            <size>0.02 0.017 0.065</size>
          </box>
        </geometry>
        <surface>
          <contact>
            <ode>
              <kp>1e+06</kp>
              <kd>1</kd>
            </ode>
          </contact>
          <friction>
            <ode>
              <mu>2000</mu>
              <mu2>1000</mu2>
            </ode>
          </friction>
        </surface>
      </collision>
      <collision name='front_left_lowerleg_collision_3'>
        <pose frame=''>0.01575 -0.0375 -0.145 0 0.04996 0</pose>
        <geometry>
          <cylinder>
            <length>0.29</length>
            <radius>0.006</radius>
          </cylinder>
        </geometry>
        <surface>
          <contact>
            <ode>
              <kp>1e+06</kp>
              <kd>1</kd>
            </ode>
          </contact>
          <friction>
            <ode>
              <mu>2000</mu>
              <mu2>1000</mu2>
            </ode>
          </friction>
        </surface>
      </collision>
      <collision name='front_left_lowerleg_collision_4'>
        <pose frame=''>-0.01575 -0.0375 -0.145 0 -0.04996 0</pose>
        <geometry>
          <cylinder>
            <length>0.29</length>
            <radius>0.006</radius>
          </cylinder>
        </geometry>
        <surface>
          <contact>
            <ode>
              <kp>1e+06</kp>
              <kd>1</kd>
            </ode>
          </contact>
          <friction>
            <ode>
              <mu>2000</mu>
              <mu2>1000</mu2>
            </ode>
          </friction>
        </surface>
      </collision>
      <collision name='front_left_lowerleg_fixed_joint_lump__front_left_foot_collision_5'>
        <pose frame=''>0 -0.035 -0.3 0 -0 0</pose>
        <geometry>
          <sphere>
            <radius>0.028</radius>
          </sphere>
        </geometry>
        <surface>
          <contact>
            <ode>
              <kp>1e+06</kp>
              <kd>1</kd>
            </ode>
          </contact>
          <friction>
            <ode>
              <mu>2000</mu>
              <mu2>1000</mu2>
            </ode>
          </friction>
        </surface>
      </collision>
      <visual name='front_left_lowerleg_visual'>
        <pose frame=''>0 0 0 -1.5708 0 0</pose>
        <geometry>
          <mesh>
            <scale>1 1 1</scale>
            <uri>model://dogbot_description/meshes/LegLower_nofoot.dae</uri>
          </mesh>
        </geometry>
        <material>
          <script>
            <uri>__default__</uri>
            <name>__default__</name>
          </script>
        </material>
      </visual>
      <visual name='front_left_lowerleg_fixed_joint_lump__front_left_foot_visual_1'>
        <pose frame=''>0 0 0 -1.5708 0 0</pose>
        <geometry>
          <mesh>
            <scale>1 1 1</scale>
            <uri>model://dogbot_description/meshes/foot.dae</uri>
          </mesh>
        </geometry>
        <material>
          <script>
            <uri>__default__</uri>
            <name>__default__</name>
          </script>
        </material>
      </visual>
      <velocity_decay/>
      <self_collide>1</self_collide>
      <gravity>1</gravity>
      <velocity_decay/>
      <sensor name='front_left_contactsensor_sensor' type='contact'>
        <always_on>1</always_on>
        <contact>
          <collision>front_left_lowerleg_fixed_joint_lump__front_left_foot_collision_5</collision>
          <topic>__default_topic__</topic>
        </contact>
        <plugin name='front_left_foot_plugin' filename='libgazebo_ros_bumper.so'>
          <bumperTopicName>front_left_contactsensor_state</bumperTopicName>
          <frameName>world</frameName>
        </plugin>
        <pose frame=''>0 0 0 0 -0 0</pose>
      </sensor>
    </link>
    <joint name='front_left_knee_joint' type='revolute'>
      <child>front_left_lowerleg</child>
      <parent>front_left_upperleg</parent>
      <axis>
        <xyz>1 0 0</xyz>
        <limit>
          <lower>-2.61795</lower>
          <upper>0.02</upper>
          <effort>60</effort>
          <velocity>6</velocity>
        </limit>
        <dynamics>
          <spring_reference>0</spring_reference>
          <spring_stiffness>0</spring_stiffness>
        </dynamics>
        <use_parent_model_frame>1</use_parent_model_frame>
      </axis>
    </joint>
    <link name='front_right_hip'>
      <pose frame=''>0.088 0.2875 0 0 -0 0</pose>
      <inertial>
        <pose frame=''>0.0074 0 0 0 -0 0</pose>
        <mass>0.836</mass>
        <inertia>
          <ixx>0.00213</ixx>
          <ixy>0</ixy>
          <ixz>0</ixz>
          <iyy>0.00147</iyy>
          <iyz>0</iyz>
          <izz>0.00172</izz>
        </inertia>
      </inertial>
      <collision name='front_right_hip_collision'>
        <pose frame=''>0.02 0 0 3.14159 1.57079 3.14159</pose>
        <geometry>
          <cylinder>
            <length>0.08</length>
            <radius>0.0525</radius>
          </cylinder>
        </geometry>
      </collision>
      <visual name='front_right_hip_visual'>
        <pose frame=''>0 0 0 -1.5708 0 0</pose>
        <geometry>
          <mesh>
            <scale>1 1 1</scale>
            <uri>model://dogbot_description/meshes/hip.dae</uri>
          </mesh>
        </geometry>
      </visual>
    </link>
    <joint name='front_right_roll_joint' type='revolute'>
      <child>front_right_hip</child>
      <parent>base_link</parent>
      <axis>
        <xyz>0 1 0</xyz>
        <limit>
          <lower>-1.7453</lower>
          <upper>1.7453</upper>
          <effort>60</effort>
          <velocity>6</velocity>
        </limit>
        <dynamics>
          <spring_reference>0</spring_reference>
          <spring_stiffness>0</spring_stiffness>
        </dynamics>
        <use_parent_model_frame>1</use_parent_model_frame>
      </axis>
    </joint>
    <link name='front_right_upperleg'>
      <pose frame=''>0.18675 0.2875 0 0 -0 0</pose>
      <inertial>
        <pose frame=''>0.0418 0 -0.0517 0 -0 0</pose>
        <mass>1.851</mass>
        <inertia>
          <ixx>0.0238</ixx>
          <ixy>0</ixy>
          <ixz>0</ixz>
          <iyy>0.0252</iyy>
          <iyz>0</iyz>
          <izz>0.0044</izz>
        </inertia>
      </inertial>
      <collision name='front_right_upperleg_collision'>
        <pose frame=''>0.03 0 0 3.14159 1.57079 3.14159</pose>
        <geometry>
          <cylinder>
            <length>0.13</length>
            <radius>0.0525</radius>
          </cylinder>
        </geometry>
      </collision>
      <collision name='front_right_upperleg_collision_1'>
        <pose frame=''>0 0 -0.135 0 -0 0</pose>
        <geometry>
          <cylinder>
            <length>0.27</length>
            <radius>0.033</radius>
          </cylinder>
        </geometry>
      </collision>
      <collision name='front_right_upperleg_collision_2'>
        <pose frame=''>0 0 -0.135 0 -0 0</pose>
        <geometry>
          <box>
            <size>0.025 0.084 0.27</size>
          </box>
        </geometry>
      </collision>
      <collision name='front_right_upperleg_collision_3'>
        <pose frame=''>0.046 0 -0.126 0 -0 0</pose>
        <geometry>
          <box>
            <size>0.026 0.074 0.138</size>
          </box>
        </geometry>
      </collision>
      <collision name='front_right_upperleg_collision_4'>
        <pose frame=''>0.03 0 -0.315 3.14159 1.57079 3.14159</pose>
        <geometry>
          <cylinder>
            <length>0.018</length>
            <radius>0.017</radius>
          </cylinder>
        </geometry>
      </collision>
      <collision name='front_right_upperleg_collision_5'>
        <pose frame=''>-0.036 0 -0.315 3.14159 1.57079 3.14159</pose>
        <geometry>
          <cylinder>
            <length>0.013</length>
            <radius>0.017</radius>
          </cylinder>
        </geometry>
      </collision>
      <visual name='front_right_upperleg_visual'>
        <pose frame=''>0 0 0 -1.5708 0 0</pose>
        <geometry>
          <mesh>
            <scale>1 1 1</scale>
            <uri>model://dogbot_description/meshes/LegUpper_withCover.dae</uri>
          </mesh>
        </geometry>
      </visual>
    </link>
    <joint name='front_right_pitch_joint' type='revolute'>
      <child>front_right_upperleg</child>
      <parent>front_right_hip</parent>
      <axis>
        <xyz>1 0 0</xyz>
        <limit>
          <lower>-3.14159</lower>
          <upper>1.5708</upper>
          <effort>60</effort>
          <velocity>6</velocity>
        </limit>
        <dynamics>
          <spring_reference>0</spring_reference>
          <spring_stiffness>0</spring_stiffness>
        </dynamics>
        <use_parent_model_frame>1</use_parent_model_frame>
      </axis>
    </joint>
    <link name='front_right_lowerleg'>
      <pose frame=''>0.18675 0.2875 -0.315 0 -0 0</pose>
      <inertial>
        <pose frame=''>0 -0.028904 -0.143425 0 -0 0</pose>
        <mass>0.303</mass>
        <inertia>
          <ixx>0.00529148</ixx>
          <ixy>0</ixy>
          <ixz>0</ixz>
          <iyy>0.00511064</iyy>
          <iyz>-4.15933e-06</iyz>
          <izz>0.000800838</izz>
        </inertia>
      </inertial>
      <collision name='front_right_lowerleg_collision'>
        <pose frame=''>0 0 0 3.14159 1.57079 3.14159</pose>
        <geometry>
          <cylinder>
            <length>0.033</length>
            <radius>0.042</radius>
          </cylinder>
        </geometry>
        <surface>
          <contact>
            <ode>
              <kp>1e+06</kp>
              <kd>1</kd>
            </ode>
          </contact>
          <friction>
            <ode>
              <mu>2000</mu>
              <mu2>1000</mu2>
            </ode>
          </friction>
        </surface>
      </collision>
      <collision name='front_right_lowerleg_collision_1'>
        <pose frame=''>0.024 -0.0375 -0.0055 0 -0 0</pose>
        <geometry>
          <box>
            <size>0.02 0.017 0.065</size>
          </box>
        </geometry>
        <surface>
          <contact>
            <ode>
              <kp>1e+06</kp>
              <kd>1</kd>
            </ode>
          </contact>
          <friction>
            <ode>
              <mu>2000</mu>
              <mu2>1000</mu2>
            </ode>
          </friction>
        </surface>
      </collision>
      <collision name='front_right_lowerleg_collision_2'>
        <pose frame=''>-0.024 -0.0375 -0.0055 0 -0 0</pose>
        <geometry>
          <box>
            <size>0.02 0.017 0.065</size>
          </box>
        </geometry>
        <surface>
          <contact>
            <ode>
              <kp>1e+06</kp>
              <kd>1</kd>
            </ode>
          </contact>
          <friction>
            <ode>
              <mu>2000</mu>
              <mu2>1000</mu2>
            </ode>
          </friction>
        </surface>
      </collision>
      <collision name='front_right_lowerleg_collision_3'>
        <pose frame=''>0.01575 -0.0375 -0.145 0 0.04996 0</pose>
        <geometry>
          <cylinder>
            <length>0.29</length>
            <radius>0.006</radius>
          </cylinder>
        </geometry>
        <surface>
          <contact>
            <ode>
              <kp>1e+06</kp>
              <kd>1</kd>
            </ode>
          </contact>
          <friction>
            <ode>
              <mu>2000</mu>
              <mu2>1000</mu2>
            </ode>
          </friction>
        </surface>
      </collision>
      <collision name='front_right_lowerleg_collision_4'>
        <pose frame=''>-0.01575 -0.0375 -0.145 0 -0.04996 0</pose>
        <geometry>
          <cylinder>
            <length>0.29</length>
            <radius>0.006</radius>
          </cylinder>
        </geometry>
        <surface>
          <contact>
            <ode>
              <kp>1e+06</kp>
              <kd>1</kd>
            </ode>
          </contact>
          <friction>
            <ode>
              <mu>2000</mu>
              <mu2>1000</mu2>
            </ode>
          </friction>
        </surface>
      </collision>
      <collision name='front_right_lowerleg_fixed_joint_lump__front_right_foot_collision_5'>
        <pose frame=''>0 -0.035 -0.3 0 -0 0</pose>
        <geometry>
          <sphere>
            <radius>0.028</radius>
          </sphere>
        </geometry>
        <surface>
          <contact>
            <ode>
              <kp>1e+06</kp>
              <kd>1</kd>
            </ode>
          </contact>
          <friction>
            <ode>
              <mu>2000</mu>
              <mu2>1000</mu2>
            </ode>
          </friction>
        </surface>
      </collision>
      <visual name='front_right_lowerleg_visual'>
        <pose frame=''>0 0 0 -1.5708 0 0</pose>
        <geometry>
          <mesh>
            <scale>1 1 1</scale>
            <uri>model://dogbot_description/meshes/LegLower_nofoot.dae</uri>
          </mesh>
        </geometry>
        <material>
          <script>
            <uri>__default__</uri>
            <name>__default__</name>
          </script>
        </material>
      </visual>
      <visual name='front_right_lowerleg_fixed_joint_lump__front_right_foot_visual_1'>
        <pose frame=''>0 0 0 -1.5708 0 0</pose>
        <geometry>
          <mesh>
            <scale>1 1 1</scale>
            <uri>model://dogbot_description/meshes/foot.dae</uri>
          </mesh>
        </geometry>
        <material>
          <script>
            <uri>__default__</uri>
            <name>__default__</name>
          </script>
        </material>
      </visual>
      <velocity_decay/>
      <self_collide>1</self_collide>
      <gravity>1</gravity>
      <velocity_decay/>
      <sensor name='front_right_contactsensor_sensor' type='contact'>
        <always_on>1</always_on>
        <contact>
          <collision>front_right_lowerleg_fixed_joint_lump__front_right_foot_collision_5</collision>
          <topic>__default_topic__</topic>
        </contact>
        <plugin name='front_right_foot_plugin' filename='libgazebo_ros_bumper.so'>
          <bumperTopicName>front_right_contactsensor_state</bumperTopicName>
          <frameName>world</frameName>
        </plugin>
        <pose frame=''>0 0 0 0 -0 0</pose>
      </sensor>
    </link>
    <joint name='front_right_knee_joint' type='revolute'>
      <child>front_right_lowerleg</child>
      <parent>front_right_upperleg</parent>
      <axis>
        <xyz>-1 0 0</xyz>
        <limit>
          <lower>-0.02</lower>
          <upper>2.61795</upper>
          <effort>60</effort>
          <velocity>6</velocity>
        </limit>
        <dynamics>
          <spring_reference>0</spring_reference>
          <spring_stiffness>0</spring_stiffness>
        </dynamics>
        <use_parent_model_frame>1</use_parent_model_frame>
      </axis>
    </joint>
    <plugin name='imu_plugin' filename='libhector_gazebo_ros_imu.so'>
      <alwaysOn>1</alwaysOn>
      <robotNamespace>dogbot</robotNamespace>
      <topicName>imu</topicName>
      <serviceName>imu_service</serviceName>
      <gaussianNoise>0.0</gaussianNoise>
      <updateRate>20.0</updateRate>
      <bodyName>base_link</bodyName>
      <xyzOffset>0 0 0</xyzOffset>
      <rpyOffset>0 -0 0</rpyOffset>
    </plugin>
    <plugin name='gps_plugin' filename='libhector_gazebo_ros_gps.so'>
      <alwaysOn>1</alwaysOn>
      <robotNamespace>dogbot</robotNamespace>
      <topicName>gps</topicName>
      <serviceName>imu_service</serviceName>
      <updateRate>100</updateRate>
      <referenceLatitude>51.5</referenceLatitude>
      <referenceLongitude>0.1278</referenceLongitude>
      <bodyName>base_link</bodyName>
      <xyzOffset>0 0 0</xyzOffset>
      <rpyOffset>0 -0 0</rpyOffset>
    </plugin>
    <plugin name='com_plugin' filename='libcom_plugin.so'/>
    <plugin name='acom_plugin' filename='libacom_plugin.so'/>
    <plugin name='vcom_plugin' filename='libvcom_plugin.so'/>
    <plugin name='p_body_plugin' filename='libp_body_plugin.so'/>
    <plugin name='v_body_plugin' filename='libv_body_plugin.so'/>
    <plugin name='force_plugin' filename='libforce_plugin.so'/>
    <static>0</static>
    <plugin name='gazebo_ros_control' filename='libgazebo_ros_control.so'>
      <robotNamespace>/dogbot</robotNamespace>
    </plugin>
  </model>
</sdf>
